<?xml version="1.0" encoding="utf-8"?>
<!-- This URDF was automatically created by SolidWorks to URDF Exporter! Originally created by Stephen Brawner (brawner@gmail.com) 
     Commit Version: 1.6.0-4-g7f85cfe  Build Version: 1.6.7995.38578
     For more information, please see http://wiki.ros.org/sw_urdf_exporter -->
<robot
  name="robot_description_v2">
  <link
    name="base_link">
    <inertial>
      <origin
        xyz="0.0238435989874038 -0.00183858987047597 0.0585774485630484"
        rpy="0 0 0" />
      <mass
        value="9.16292167966058" />
      <inertia
        ixx="0.0303098706909851"
        ixy="-0.000262551161897404"
        ixz="0.000472148054425571"
        iyy="0.0534307098467186"
        iyz="-6.76436725828456E-07"
        izz="0.0734304007880829" />
    </inertial>
    <visual>
      <origin
        xyz="0 0 0"
        rpy="0 0 0" />
      <geometry>
        <mesh
          filename="package://robot_description_v2/meshes/base_link.STL" />
      </geometry>
      <material
        name="">
        <color
          rgba="0.752941176470588 0.752941176470588 0.752941176470588 1" />
      </material>
    </visual>
    <collision>
      <origin
        xyz="0 0 0"
        rpy="0 0 0" />
      <geometry>
        <mesh
          filename="package://robot_description_v2/meshes/base_link.STL" />
      </geometry>
    </collision>
  </link>
  <link
    name="lidar_link">
    <inertial>
      <origin
        xyz="0.0148383171347257 0.000447683431163026 -0.0911536208242788"
        rpy="0 0 0" />
      <mass
        value="0.0312409127406485" />
      <inertia
        ixx="8.88026370811002E-06"
        ixy="-1.77664494330377E-07"
        ixz="1.13027679917078E-07"
        iyy="1.44910018205435E-05"
        iyz="3.4607611499625E-08"
        izz="2.25289099520271E-05" />
    </inertial>
    <visual>
      <origin
        xyz="0 0 0"
        rpy="0 0 0" />
      <geometry>
        <mesh
          filename="package://robot_description_v2/meshes/lidar_link.STL" />
      </geometry>
      <material
        name="">
        <color
          rgba="0.792156862745098 0.819607843137255 0.933333333333333 1" />
      </material>
    </visual>
    <collision>
      <origin
        xyz="0 0 0"
        rpy="0 0 0" />
      <geometry>
        <mesh
          filename="package://robot_description_v2/meshes/lidar_link.STL" />
      </geometry>
    </collision>
  </link>
  <joint
    name="lidar"
    type="fixed">
    <origin
      xyz="0.155666725645511 0.00112777065618036 0.216100000004219"
      rpy="0 0 0" />
    <parent
      link="base_link" />
    <child
      link="lidar_link" />
    <axis
      xyz="0 0 0" />
  </joint>
  <link
    name="imu_link">
    <inertial>
      <origin
        xyz="-0.000128980117751309 -0.000191495598006186 -0.00384070509348666"
        rpy="0 0 0" />
      <mass
        value="0.00099989811898683" />
      <inertia
        ixx="2.50447716935415E-08"
        ixy="1.03965056246901E-10"
        ixz="-2.68560481392878E-14"
        iyy="1.2451353550853E-08"
        iyz="-1.18565423317864E-14"
        izz="3.06376353115898E-08" />
    </inertial>
    <visual>
      <origin
        xyz="0 0 0"
        rpy="0 0 0" />
      <geometry>
        <mesh
          filename="package://robot_description_v2/meshes/imu_link.STL" />
      </geometry>
      <material
        name="">
        <color
          rgba="0.792156862745098 0.819607843137255 0.933333333333333 1" />
      </material>
    </visual>
    <collision>
      <origin
        xyz="0 0 0"
        rpy="0 0 0" />
      <geometry>
        <mesh
          filename="package://robot_description_v2/meshes/imu_link.STL" />
      </geometry>
    </collision>
  </link>
  <joint
    name="imu"
    type="fixed">
    <origin
      xyz="0.126428933055049 -0.100523077234269 0.0330200000034927"
      rpy="0 0 0" />
    <parent
      link="base_link" />
    <child
      link="imu_link" />
    <axis
      xyz="0 0 0" />
  </joint>
  <link
    name="right_wheel_link">
    <inertial>
      <origin
        xyz="0.000243587829777958 -0.0295000990455644 8.01156918583956E-11"
        rpy="0 0 0" />
      <mass
        value="0.981706650902443" />
      <inertia
        ixx="0.00165298875829609"
        ixy="-1.01208993064455E-05"
        ixz="-1.81686206531272E-09"
        iyy="0.00287861061005824"
        iyz="-1.35675311985422E-11"
        izz="0.00165291235980834" />
    </inertial>
    <visual>
      <origin
        xyz="0 0 0"
        rpy="0 0 0" />
      <geometry>
        <mesh
          filename="package://robot_description_v2/meshes/right_wheel_link.STL" />
      </geometry>
      <material
        name="">
        <color
          rgba="0.2 0.2 0.2 1" />
      </material>
    </visual>
    <collision>
      <origin
        xyz="0 0 0"
        rpy="0 0 0" />
      <geometry>
        <mesh
          filename="package://robot_description_v2/meshes/right_wheel_link.STL" />
      </geometry>
    </collision>
  </link>
  <joint
    name="right_wheel"
    type="continuous">
    <origin
      xyz="0.00157556970077088 -0.175020257687692 0.0150000000042174"
      rpy="0 0 0" />
    <parent
      link="base_link" />
    <child
      link="right_wheel_link" />
    <axis
      xyz="-0.00825691107326283 0.999965911128739 0" />
  </joint>
  <link
    name="left_wheel_link">
    <inertial>
      <origin
        xyz="-0.000243587829778624 0.0295000990455639 8.01149702134296E-11"
        rpy="0 0 0" />
      <mass
        value="0.981706650902443" />
      <inertia
        ixx="0.00165299120834847"
        ixy="-1.01249109871006E-05"
        ixz="-1.44984115093078E-08"
        iyy="0.00287861950901393"
        iyz="7.25004217184161E-11"
        izz="0.00165291988234476" />
    </inertial>
    <visual>
      <origin
        xyz="0 0 0"
        rpy="0 0 0" />
      <geometry>
        <mesh
          filename="package://robot_description_v2/meshes/left_wheel_link.STL" />
      </geometry>
      <material
        name="">
        <color
          rgba="0.2 0.2 0.2 1" />
      </material>
    </visual>
    <collision>
      <origin
        xyz="0 0 0"
        rpy="0 0 0" />
      <geometry>
        <mesh
          filename="package://robot_description_v2/meshes/left_wheel_link.STL" />
      </geometry>
    </collision>
  </link>
  <joint
    name="left_wheel"
    type="continuous">
    <origin
      xyz="-0.00131434917487327 0.174967811207364 0.0150000000042175"
      rpy="0 0 0" />
    <parent
      link="base_link" />
    <child
      link="left_wheel_link" />
    <axis
      xyz="0.00825691107326281 -0.999965911128739 0" />
  </joint>
  <link
    name="cam_link">
    <inertial>
      <origin
        xyz="-0.0286974043856941 -0.00315323141543045 -0.00696427170361802"
        rpy="0 0 0" />
      <mass
        value="0.646454884722171" />
      <inertia
        ixx="0.0028423827313704"
        ixy="1.87273045722636E-05"
        ixz="1.48075090936093E-07"
        iyy="0.000263758634244186"
        iyz="-3.33736128214463E-08"
        izz="0.00296274058967308" />
    </inertial>
    <visual>
      <origin
        xyz="0 0 0"
        rpy="0 0 0" />
      <geometry>
        <mesh
          filename="package://robot_description_v2/meshes/cam_link.STL" />
      </geometry>
      <material
        name="">
        <color
          rgba="0.752941176470588 0.752941176470588 0.752941176470588 1" />
      </material>
    </visual>
    <collision>
      <origin
        xyz="0 0 0"
        rpy="0 0 0" />
      <geometry>
        <mesh
          filename="package://robot_description_v2/meshes/cam_link.STL" />
      </geometry>
    </collision>
  </link>
  <joint
    name="cam"
    type="fixed">
    <origin
      xyz="0.264952270554911 0.00535821231736117 0.284425164615102"
      rpy="0 0 0" />
    <parent
      link="base_link" />
    <child
      link="cam_link" />
    <axis
      xyz="0 0 0" />
  </joint>
</robot>