<?xml version="1.0" encoding="utf-8"?>
<!-- This URDF was automatically created by SolidWorks to URDF Exporter! Originally created by Stephen Brawner (brawner@gmail.com) 
     Commit Version: 1.6.0-4-g7f85cfe  Build Version: 1.6.7995.38578
     For more information, please see http://wiki.ros.org/sw_urdf_exporter -->
<robot
  name="robot_description_v3">
  <link
    name="base_link">
    <inertial>
      <origin
        xyz="0.0227806917637081 -0.00439476349875706 0.0586045786954241"
        rpy="0 0 0" />
      <mass
        value="9.20179187544468" />
      <inertia
        ixx="0.0310745431127652"
        ixy="-0.000256263088842519"
        ixz="0.000472148054425571"
        iyy="0.0534339074346466"
        iyz="-6.76436725828867E-07"
        izz="0.074195125131693" />
    </inertial>
    <visual>
      <origin
        xyz="0 0 0"
        rpy="0 0 0" />
      <geometry>
        <mesh
          filename="package://robot_description_v3/meshes/base_link.STL" />
      </geometry>
      <material
        name="">
        <color
          rgba="0.752941176470588 0.752941176470588 0.752941176470588 1" />
      </material>
    </visual>
    <collision>
      <origin
        xyz="0 0 0"
        rpy="0 0 0" />
      <geometry>
        <mesh
          filename="package://robot_description_v3/meshes/base_link.STL" />
      </geometry>
    </collision>
  </link>
  <link
    name="lidar_link">
    <inertial>
      <origin
        xyz="0.0148383171348765 0.000447683431151313 -0.0911536208248785"
        rpy="0 0 0" />
      <mass
        value="0.0312409127404853" />
      <inertia
        ixx="8.88026370808507E-06"
        ixy="-1.77664494264075E-07"
        ixz="1.13027679908936E-07"
        iyy="1.4491001820374E-05"
        iyz="3.46076114958862E-08"
        izz="2.25289099518331E-05" />
    </inertial>
    <visual>
      <origin
        xyz="0 0 0"
        rpy="0 0 0" />
      <geometry>
        <mesh
          filename="package://robot_description_v3/meshes/lidar_link.STL" />
      </geometry>
      <material
        name="">
        <color
          rgba="0.792156862745098 0.819607843137255 0.933333333333333 1" />
      </material>
    </visual>
    <collision>
      <origin
        xyz="0 0 0"
        rpy="0 0 0" />
      <geometry>
        <mesh
          filename="package://robot_description_v3/meshes/lidar_link.STL" />
      </geometry>
    </collision>
  </link>
  <joint
    name="lidar"
    type="fixed">
    <origin
      xyz="0.155666725645511 0.00112777065618036 0.216100000004219"
      rpy="0 0 0" />
    <parent
      link="base_link" />
    <child
      link="lidar_link" />
    <axis
      xyz="0 0 0" />
  </joint>
  <link
    name="imu_link">
    <inertial>
      <origin
        xyz="-0.000128980117747868 -0.000191495597993335 -0.00384070509348688"
        rpy="0 0 0" />
      <mass
        value="0.000999898118986841" />
      <inertia
        ixx="2.50447716935416E-08"
        ixy="1.0396505624692E-10"
        ixz="-2.68560481634615E-14"
        iyy="1.24513535508531E-08"
        iyz="-1.18565423488172E-14"
        izz="3.06376353115898E-08" />
    </inertial>
    <visual>
      <origin
        xyz="0 0 0"
        rpy="0 0 0" />
      <geometry>
        <mesh
          filename="package://robot_description_v3/meshes/imu_link.STL" />
      </geometry>
      <material
        name="">
        <color
          rgba="0.792156862745098 0.819607843137255 0.933333333333333 1" />
      </material>
    </visual>
    <collision>
      <origin
        xyz="0 0 0"
        rpy="0 0 0" />
      <geometry>
        <mesh
          filename="package://robot_description_v3/meshes/imu_link.STL" />
      </geometry>
    </collision>
  </link>
  <joint
    name="imu"
    type="fixed">
    <origin
      xyz="0.126428933055049 -0.100523077234269 0.0330200000034927"
      rpy="0 0 0" />
    <parent
      link="base_link" />
    <child
      link="imu_link" />
    <axis
      xyz="0 0 0" />
  </joint>
  <link
    name="right_wheel_link">
    <inertial>
      <origin
        xyz="0.000243587829777736 -0.0295000990455644 8.01158028806981E-11"
        rpy="0 0 0" />
      <mass
        value="0.981706650902442" />
      <inertia
        ixx="0.00165298875829608"
        ixy="-1.01208993064455E-05"
        ixz="-1.81686206584513E-09"
        iyy="0.00287861061005824"
        iyz="-1.35675306260573E-11"
        izz="0.00165291235980834" />
    </inertial>
    <visual>
      <origin
        xyz="0 0 0"
        rpy="0 0 0" />
      <geometry>
        <mesh
          filename="package://robot_description_v3/meshes/right_wheel_link.STL" />
      </geometry>
      <material
        name="">
        <color
          rgba="0.2 0.2 0.2 1" />
      </material>
    </visual>
    <collision>
      <origin
        xyz="0 0 0"
        rpy="0 0 0" />
      <geometry>
        <mesh
          filename="package://robot_description_v3/meshes/right_wheel_link.STL" />
      </geometry>
    </collision>
  </link>
  <joint
    name="right_wheel"
    type="continuous">
    <origin
      xyz="0.00157556970077088 -0.175020257687692 0.0150000000042174"
      rpy="0 0 0" />
    <parent
      link="base_link" />
    <child
      link="right_wheel_link" />
    <axis
      xyz="-0.00825691107326283 0.999965911128739 0" />
  </joint>
  <link
    name="left_wheel_link">
    <inertial>
      <origin
        xyz="-0.000243587829778624 0.0295000990455639 8.01149702134296E-11"
        rpy="0 0 0" />
      <mass
        value="0.981706650902443" />
      <inertia
        ixx="0.00165299120834847"
        ixy="-1.01249109871006E-05"
        ixz="-1.44984115093218E-08"
        iyy="0.00287861950901393"
        iyz="7.25004217168263E-11"
        izz="0.00165291988234476" />
    </inertial>
    <visual>
      <origin
        xyz="0 0 0"
        rpy="0 0 0" />
      <geometry>
        <mesh
          filename="package://robot_description_v3/meshes/left_wheel_link.STL" />
      </geometry>
      <material
        name="">
        <color
          rgba="0.2 0.2 0.2 1" />
      </material>
    </visual>
    <collision>
      <origin
        xyz="0 0 0"
        rpy="0 0 0" />
      <geometry>
        <mesh
          filename="package://robot_description_v3/meshes/left_wheel_link.STL" />
      </geometry>
    </collision>
  </link>
  <joint
    name="left_wheel"
    type="continuous">
    <origin
      xyz="-0.00131434917487327 0.174967811207364 0.0150000000042175"
      rpy="0 0 0" />
    <parent
      link="base_link" />
    <child
      link="left_wheel_link" />
    <axis
      xyz="0.00825691107326281 -0.999965911128739 0" />
  </joint>
  <link
    name="camera_link">
    <inertial>
      <origin
        xyz="-0.0286974043856941 -0.00315323141543045 -0.00696427170361802"
        rpy="0 0 0" />
      <mass
        value="0.646454884722171" />
      <inertia
        ixx="0.0028423827313704"
        ixy="1.87273045722636E-05"
        ixz="1.48075090936103E-07"
        iyy="0.000263758634244186"
        iyz="-3.33736128214585E-08"
        izz="0.00296274058967308" />
    </inertial>
    <visual>
      <origin
        xyz="0 0 0"
        rpy="0 0 0" />
      <geometry>
        <mesh
          filename="package://robot_description_v3/meshes/camera_link.STL" />
      </geometry>
      <material
        name="">
        <color
          rgba="0.752941176470588 0.752941176470588 0.752941176470588 1" />
      </material>
    </visual>
    <collision>
      <origin
        xyz="0 0 0"
        rpy="0 0 0" />
      <geometry>
        <mesh
          filename="package://robot_description_v3/meshes/camera_link.STL" />
      </geometry>
    </collision>
  </link>
  <joint
    name="cam"
    type="fixed">
    <origin
      xyz="0.26495 0.0053582 0.28443"
      rpy="0 0 0" />
    <parent
      link="base_link" />
    <child
      link="camera_link" />
    <axis
      xyz="0 0 0" />
  </joint>
</robot>